<?xml version="1.0"?>
<robot xmlns:xacro="http://www.ros.org/wiki/xacro" name="unist_manipulator5a">
    <material name="black">
        <color rgba="0.0 0.0 0.0 1.0"/>
    </material>
    <material name="orange">
        <color rgba="1.0 0.4 0.0 1.0"/>
    </material>
    
    <link name="world"/>>

    <joint name="fixed" type="fixed">
        <parent link="world"/>
        <child link="base_link"/>
    </joint>
    
    <link name="base_link">

        <visual>
            <origin xyz="0.0 0.135 0.0" rpy="0.0 0.0 0.0"/>
            <geometry>
                <box size ="0.196 0.27 0.28" />
            </geometry>
            <material name="orange"/>
        </visual>
    </link>

    <joint name="Joint1" type="revolute">
        <origin xyz="0.0 0.27 0.0" rpy="0.0 0.0 0.0" />
        <parent link="base_link"/>
        <child link="link_1"/>
        <axis xyz="1.0 0.0 0.0"/>
        <limit effort="1.91" lower="-1.57" upper="1.57" velocity="1.0"/>
    </joint>

    <link name="link_1">
        <visual>
            <origin xyz="0.0 0.0 -0.165" rpy="0.0 0.0 0.0" />
            <geometry>
                <box size="0.05 0.05 -0.33"/>
            </geometry>
            <material name="black"/>
        </visual>
    </link>

    <joint name="Joint2" type="revolute">
        <origin xyz="0.0 0.0 -0.33" rpy="0.0 0.0 0.0" />
        <parent link="link_1"/>
        <child link="link_2"/>
        <axis xyz="1.0 0.0 0.0"/>
        <limit effort="1.91" lower="-1.57" upper="1.57" velocity="1.0"/>
    </joint>

    <link name="link_2">
        <visual>
            <origin xyz="0.0 0.04 0" rpy="0.0 0.0 0.0" />
            <geometry>
                <box size="0.05 0.08 0.05"/>
            </geometry>
            <material name="orange"/>
        </visual>
    </link>

    <joint name="Joint_3" type="revolute">
        <origin xyz="0.0 0.08 0.0" rpy="0.0 0.0 0.0" />
        <parent link="link_2"/>
        <child link="link_3"/>
        <axis xyz="0.0 0.0 1.0"/>
        <limit effort="1.27" lower="-1.57" upper="1.57" velocity="1.0"/>
    </joint>

    <link name="link_3">
        <visual>
            <origin xyz="0.0 0.10175 0.0" rpy="0.0 0.0 0.0" />
            <geometry>
                <box size="0.05 0.2035 0.05"/>
            </geometry>
            <material name="black"/>
        </visual>
    </link>

    <joint name="Joint_4" type="revolute">
        <origin xyz="0.0 0.2035 0.0" rpy="0.0 0.0 0.0" />
        <parent link="link_3"/>
        <child link="link_4"/>
        <axis xyz="0.0 1.0 0.0"/>
        <limit effort="0.318" lower="-3.14" upper="3.14" velocity="1.0"/>
    </joint>

    <link name="link_4">
        <visual>
            <origin xyz="0.0 0.04825 0.0" rpy="0.0 0.0 0.0" />
            <geometry>
                <box size="0.05 0.0965 0.05"/>
            </geometry>
            <material name="orange"/>
        </visual>
    </link>

    <joint name="Joint_5" type="revolute">
        <origin xyz="0.0 0.0965 0.0" rpy="0.0 0.0 0.0" />
        <parent link="link_4"/>
        <child link="link_5"/>
        <axis xyz="1.0 0.0 0.0"/>
        <limit effort="0.318" lower="-1.57" upper="1.57" velocity="1.0"/>
    </joint>

    <link name="link_5">
        <visual>
            <origin xyz="0.0 0.0 -0.1" rpy="0.0 0.0 0.0" />
            <geometry>
                <box size="0.05 0.05 0.2"/>
            </geometry>
            <material name="black"/>
        </visual>
    </link>

    <joint name="Joint_6" type="revolute">
        <origin xyz="0.0 0.0 -0.2" rpy="0.0 0.0 0.0" />
        <parent link="link_5"/>
        <child link="link_6"/>
        <axis xyz="0.0 0.0 1.0"/>
        <limit effort="3.08" lower="-3.14" upper="3.14" velocity="1.0"/>
    </joint>

    <link name="link_6">
        <visual>
            <origin xyz="0.0 0.0 -0.001" rpy="0.0 0.0 0.0" />
            <geometry>
                <cylinder length="-0.002" radius="0.1"/>
            </geometry>
            <material name="orange"/>
        </visual>
    </link>
</robot>